<?xml version="1.0" encoding="utf-8"?>
<!-- This URDF was automatically created by SolidWorks to URDF Exporter! Originally created by Stephen Brawner (brawner@gmail.com) 
     Commit Version: 1.6.0-4-g7f85cfe  Build Version: 1.6.7995.38578
     For more information, please see http://wiki.ros.org/sw_urdf_exporter -->
<robot
  name="lns_robot" xmlns:xacro="http://ros.org/wiki/xacro">
  <xacro:include filename="$(find lns_description)/urdf/lns_robot_gazebo.xacro"/>
  <xacro:include filename="$(find lns_description)/urdf/lns_robot_control_transmission.xacro"/>



  <link name="base_footprint"/>
  
  <joint name="base_joint" type="fixed">
    <parent link="base_footprint"/>
    <child link="base_link"/>
    <origin xyz="0.0 0.0 0.5" rpy="0 0 0"/>
  </joint> 


  <link
    name="base_link">
    <inertial>
      <origin
        xyz="0 0 0"
        rpy="0 0 0" />
      <mass
        value="17.59" />
      <inertia
        ixx="0.4691"
        ixy="0"
        ixz="0"
        iyy="3.1076"
        iyz="0"
        izz="3.1076" />
    </inertial>
    <visual>
      <origin
        xyz="0 0 0"
        rpy="0 0 0" />
      <geometry>
        <mesh
          filename="package://lns_description/meshes/base_link.STL" />
      </geometry>
      <material
        name="">
        <color
          rgba="0.792156862745098 0.819607843137255 0.933333333333333 1" />
      </material>
    </visual>
    <collision>
      <origin
        xyz="0 0 0"
        rpy="0 0 0" />
      <geometry>
        <box size="1.48 0.4 0.4" />
      </geometry>
    </collision>
  </link>
  <link
    name="gps_link">
    <inertial>
      <origin
        xyz="-0.00039033687859702 -1.53079096248954E-05 -0.000592327383379221"
        rpy="0 0 0" />
      <mass
        value="0.195506924984229" />
      <inertia
        ixx="0.000195294443337896"
        ixy="-5.19265291636756E-07"
        ixz="-9.13195474661165E-09"
        iyy="8.18066717719668E-05"
        iyz="-5.5911022943428E-09"
        izz="0.000248825415558086" />
    </inertial>
    <visual>
      <origin
        xyz="0 0 0"
        rpy="0 0 0" />
      <geometry>
        <mesh
          filename="package://lns_description/meshes/gps_link.STL" />
      </geometry>
      <material
        name="">
        <color
          rgba="0.792156862745098 0.819607843137255 0.933333333333333 1" />
      </material>
    </visual>
  </link>
  <joint
    name="gps_joint"
    type="fixed">
    <origin
      xyz="0.7195 -8.0445E-05 0.8612"
      rpy="0 0 0" />
    <parent
      link="base_link" />
    <child
      link="gps_link" />
    <axis
      xyz="0 0 0" />
  </joint>
  <link
    name="imu_link">
    <inertial>
      <origin
        xyz="0.00314804410618519 0.000886573216435982 -0.000493504453682236"
        rpy="0 0 0" />
      <mass
        value="0.019931290489835" />
      <inertia
        ixx="6.18644586656033E-06"
        ixy="5.13081146570535E-08"
        ixz="-5.03594367346625E-08"
        iyy="4.79889383234348E-06"
        iyz="-5.65169719050544E-09"
        izz="8.20604958309782E-06" />
    </inertial>
    <visual>
      <origin
        xyz="0 0 0"
        rpy="0 0 0" />
      <geometry>
        <mesh
          filename="package://lns_description/meshes/imu_link.STL" />
      </geometry>
      <material
        name="">
        <color
          rgba="0.792156862745098 0.819607843137255 0.933333333333333 1" />
      </material>
    </visual>
    <collision>
      <origin
        xyz="0.25 0.465 0"
        rpy="0 0 0" />
      <geometry>
        <box size="1.45 1.2 0.2" />
      </geometry>
    </collision>
  </link>
  <joint
    name="imu_joint"
    type="fixed">
    <origin
      xyz="-0.25035 -0.46578 0.3661"
      rpy="0 0 0" />
    <parent
      link="base_link" />
    <child
      link="imu_link" />
    <axis
      xyz="0 0 0" />
  </joint>
  <link
    name="steering_fl_link">
    <inertial>
      <origin
        xyz="0 0 0"
        rpy="0 0 0" />
      <mass
        value="0.29" />
      <inertia
        ixx="5.3495E-4"
        ixy="0"
        ixz="0"
        iyy="5.3495E-4"
        iyz="0"
        izz="4.3069E-4" />
    </inertial>
    <visual>
      <origin
        xyz="0 0 0"
        rpy="0 0 0" />
      <geometry>
        <mesh
          filename="package://lns_description/meshes/steering_fl_link.STL" />
      </geometry>
      <material
        name="">
        <color
          rgba="0.792156862745098 0.819607843137255 0.933333333333333 1" />
      </material>
    </visual>
    <collision>
      <origin
        xyz="0 -0.16 -0.25"
        rpy="0 0 0" />
      <geometry>
        <box size="0.25 0.1 0.5" />
      </geometry>
    </collision>
  </link>
  <joint
    name="steering_fl_joint"
    type="revolute">
    <origin
      xyz="0.5 0.49992 0.1388"
      rpy="0 0 0" />
    <parent
      link="base_link" />
    <child
      link="steering_fl_link" />
    <axis
      xyz="0 0 1" />
    <limit
      lower="-2.1"
      upper="2.1"
      effort="5"
      velocity="6.28" />
  </joint>
  <link
    name="wheel_fl_link">
    <inertial>
      <origin
        xyz="0 0.023 0"
        rpy="1.57 0 0" />
      <mass
        value="1.1" />
      <inertia
        ixx="0.0133"
        ixy="0"
        ixz="0"
        iyy="0.0133"
        iyz="0"
        izz="0.022" />
    </inertial>
    <visual>
      <origin
        xyz="0 0 0"
        rpy="0 0 0" />
      <geometry>
        <mesh
          filename="package://lns_description/meshes/wheel_fl_link.STL" />
      </geometry>
      <material
        name="">
        <color
          rgba="0.792156862745098 0.819607843137255 0.933333333333333 1" />
      </material>
    </visual>
    <collision>
      <origin
        xyz="0 0.025 0"
        rpy="1.5705963 0 0" />
      <geometry>
        <cylinder length="0.16" radius="0.2" />
      </geometry>
    </collision>
  </link>
  <joint
    name="wheel_fl_joint"
    type="continuous">
    <origin
      xyz="0 -0.023 -0.433"
      rpy="0 0 0" />
    <parent
      link="steering_fl_link" />
    <child
      link="wheel_fl_link" />
    <axis
      xyz="-0.0003039 1 0" />
    <limit
      effort="1000"
      velocity="20" />
  </joint>
  <link
    name="steering_fr_link">
    <inertial>
      <origin
        xyz="0 0 0"
        rpy="0 0 0" />
      <mass
        value="0.29" />
      <inertia
        ixx="5.3495E-4"
        ixy="0"
        ixz="0"
        iyy="5.3495E-4"
        iyz="0"
        izz="4.3069E-4" />
    </inertial>
    <visual>
      <origin
        xyz="0 0 0"
        rpy="0 0 0" />
      <geometry>
        <mesh
          filename="package://lns_description/meshes/steering_fr_link.STL" />
      </geometry>
      <material
        name="">
        <color
          rgba="0.792156862745098 0.819607843137255 0.933333333333333 1" />
      </material>
    </visual>
    <collision>
      <origin
        xyz="0 0.16 -0.25"
        rpy="0 0 0" />
      <geometry>
        <box size="0.25 0.1 0.5" />
      </geometry>
    </collision>
  </link>
  <joint
    name="steering_fr_joint"
    type="revolute">
    <origin
      xyz="0.5 -0.49758 0.1388"
      rpy="0 0 0" />
    <parent
      link="base_link" />
    <child
      link="steering_fr_link" />
    <axis
      xyz="0 0 1" />
    <limit
      lower="-2.1"
      upper="2.1"
      effort="5"
      velocity="6.28" />
  </joint>
  <link
    name="wheel_fr_link">
    <inertial>
      <origin
        xyz="0 -0.023 0"
        rpy="1.57 0 0" />
      <mass
        value="1.1" />
      <inertia
        ixx="0.0133"
        ixy="0"
        ixz="0"
        iyy="0.0133"
        iyz="0"
        izz="0.022" />
    </inertial>
    <visual>
      <origin
        xyz="0 0 0"
        rpy="0 0 0" />
      <geometry>
        <mesh
          filename="package://lns_description/meshes/wheel_fr_link.STL" />
      </geometry>
      <material
        name="">
        <color
          rgba="0.792156862745098 0.819607843137255 0.933333333333333 1" />
      </material>
    </visual>
    <collision>
      <origin
        xyz="0 -0.025 0"
        rpy="1.5705963 0 0" />
      <geometry>
        <cylinder length="0.16" radius="0.2" />
      </geometry>
    </collision>
  </link>
  <joint
    name="wheel_fr_joint"
    type="continuous">
    <origin
      xyz="-5.4024E-05 0.023 -0.433"
      rpy="0 0 0" />
    <parent
      link="steering_fr_link" />
    <child
      link="wheel_fr_link" />
    <axis
      xyz="0.0023488 1 0" />
    <limit
      effort="1000"
      velocity="20" />
  </joint>
  <link
    name="steering_br_link">
    <inertial>
      <origin
        xyz="0 0 0"
        rpy="0 0 0" />
      <mass
        value="0.29" />
      <inertia
        ixx="5.3495E-4"
        ixy="0"
        ixz="0"
        iyy="5.3495E-4"
        iyz="0"
        izz="4.3069E-4" />
    </inertial>
    <visual>
      <origin
        xyz="0 0 0"
        rpy="0 0 0" />
      <geometry>
        <mesh
          filename="package://lns_description/meshes/steering_br_link.STL" />
      </geometry>
      <material
        name="">
        <color
          rgba="0.792156862745098 0.819607843137255 0.933333333333333 1" />
      </material>
    </visual>
    <collision>
      <origin
        xyz="0 0.16 -0.25"
        rpy="0 0 0" />
      <geometry>
        <box size="0.25 0.1 0.5" />
      </geometry>
    </collision>
  </link>
  <joint
    name="steering_br_joint"
    type="revolute">
    <origin
      xyz="-0.5 -0.49758 0.1388"
      rpy="0 0 0" />
    <parent
      link="base_link" />
    <child
      link="steering_br_link" />
    <axis
      xyz="0 0 1" />
    <limit
      lower="-2.1"
      upper="2.1"
      effort="5"
      velocity="6.28" />
  </joint>
  <link
    name="wheel_br_link">
    <inertial>
      <origin
        xyz="0 -0.023 0"
        rpy="1.57 0 0" />
      <mass
        value="1.1" />
      <inertia
        ixx="0.0133"
        ixy="0"
        ixz="0"
        iyy="0.0133"
        iyz="0"
        izz="0.022" />
    </inertial>
    <visual>
      <origin
        xyz="0 0 0"
        rpy="0 0 0" />
      <geometry>
        <mesh
          filename="package://lns_description/meshes/wheel_br_link.STL" />
      </geometry>
      <material
        name="">
        <color
          rgba="0.792156862745098 0.819607843137255 0.933333333333333 1" />
      </material>
    </visual>
    <collision>
      <origin
        xyz="0 -0.025 0"
        rpy="1.5705963 0 0" />
      <geometry>
        <cylinder length="0.16" radius="0.2" />
      </geometry>
    </collision>
  </link>
  <joint
    name="wheel_br_joint"
    type="continuous">
    <origin
      xyz="-5.4024E-05 0.023 -0.433"
      rpy="0 0 0" />
    <parent
      link="steering_br_link" />
    <child
      link="wheel_br_link" />
    <axis
      xyz="0.0023488 1 0" />
    <limit
      effort="1000"
      velocity="20" />
  </joint>
  <link
    name="steering_bl_link">
    <inertial>
      <origin
        xyz="0 0 0"
        rpy="0 0 0" />
      <mass
        value="0.29" />
      <inertia
        ixx="5.3495E-4"
        ixy="0"
        ixz="0"
        iyy="5.3495E-4"
        iyz="0"
        izz="4.3069E-4" />
    </inertial>
    <visual>
      <origin
        xyz="0 0 0"
        rpy="0 0 0" />
      <geometry>
        <mesh
          filename="package://lns_description/meshes/steering_bl_link.STL" />
      </geometry>
      <material
        name="">
        <color
          rgba="0.792156862745098 0.819607843137255 0.933333333333333 1" />
      </material>
    </visual>
    <collision>
      <origin
        xyz="0 -0.16 -0.25"
        rpy="0 0 0" />
      <geometry>
        <box size="0.25 0.1 0.5" />
      </geometry>
    </collision>
  </link>
  <joint
    name="steering_bl_joint"
    type="revolute">
    <origin
      xyz="-0.5 0.49992 0.1388"
      rpy="0 0 0" />
    <parent
      link="base_link" />
    <child
      link="steering_bl_link" />
    <axis
      xyz="0 0 1" />
    <limit
      lower="-2.1"
      upper="2.1"
      effort="5"
      velocity="6.28" />
  </joint>
  <link
    name="wheel_bl_link">
    <inertial>
      <origin
        xyz="0 0.023 0"
        rpy="1.57 0 0" />
      <mass
        value="1.1" />
      <inertia
        ixx="0.0133"
        ixy="0"
        ixz="0"
        iyy="0.0133"
        iyz="0"
        izz="0.022" />
    </inertial>
    <visual>
      <origin
        xyz="0 0 0"
        rpy="0 0 0" />
      <geometry>
        <mesh
          filename="package://lns_description/meshes/wheel_bl_link.STL" />
      </geometry>
      <material
        name="">
        <color
          rgba="0.792156862745098 0.819607843137255 0.933333333333333 1" />
      </material>
    </visual>
    <collision>
      <origin
        xyz="0 0.025 0"
        rpy="1.5705963 0 0" />
      <geometry>
        <cylinder length="0.16" radius="0.2" />
      </geometry>
    </collision>
  </link>
  <joint
    name="wheel_bl_joint"
    type="continuous">
    <origin
      xyz="5.4023E-05 -0.023 -0.433"
      rpy="0 0 0" />
    <parent
      link="steering_bl_link" />
    <child
      link="wheel_bl_link" />
    <axis
      xyz="-0.0023488 1 0" />
    <limit
      effort="1000"
      velocity="20" />
  </joint>
</robot>